Workbook

Sheet README
A1: Cash discipline: cases and rules
A2: ForteBank Datathon 26. Built from the 42 training clips, open_labels.xlsx and the task brief. As of 2026-10-17.
A4: Sheets
A5: Cases | B5: Scenario types: what happens on video. Each case lists its violation clips and its correct counterparts.
A6: Rules | B6: Atomic checks: one rule = one condition the engine can test. Each rule carries its legal source and strength.
A7: Case_Rule | B7: Link table (many-to-many). Edit this to change which rules a case breaks; counts on the other sheets update.
A8: Clips | B8: Every training clip with its label, case, role (violation / correct) and what is visible.
A9: Open_Questions | B9: Decisions still to make. Your answers go in the yellow column.
A11: Legend
A12: Yellow cells | B12: Inputs for you to fill in (decisions, status).
A13: Confidence | B13: High = clear in frames; Medium = likely; Low = needs a full-resolution re-watch.
A14: Strength | B14: Direct = the clause states the rule; Indirect = the clause requires the control and the video shows it unused; Weak = no explicit clause found.
A15: Status | B15: Confirmed = rule backed by a labelled clip; Candidate = proposed (unresolved clip or unseen type).
A17: Sources (short names)
A18: NBRK 231 | B18: NBRK Board resolution No. 231 of 29.11.2019, rules for cash operations and cash collection (reg. No. 19680) | C18: https://adilet.zan.kz/rus/docs/V1900019680
A19: NBRK 14 | B19: NBRK Board resolution No. 14 of 24.02.2020, security and layout of bank premises (reg. No. 20075) | C19: https://adilet.zan.kz/rus/docs/V2000020075
A20: NBRK 48 | B20: NBRK Board resolution No. 48 of 27.03.2018, information security of banks (reg. No. 16772); repealed April 2026, successor clause to confirm | C20: https://adilet.zan.kz/rus/docs/V1800016772

Sheet Cases
A1: Case ID | B1: Scenario | C1: Phase | D1: What goes wrong | E1: What correct looks like | F1: Violation clips (label) | G1: Correct clips | H1: Timecode anchor | I1: Confidence | J1: # violation clips (primary) | K1: # correct clips (primary) | L1: # rules linked
A2: C-01 | B2: Door left unlocked on entry | C2: Opening / entry | D2: Cashier walks in and goes to the desk without turning back to close and lock the door. | E2: Cashier turns back, closes and locks the door, then goes to the desk. | F2: X-32 @5s; X-33 @6s; X-30 (entry ~3s, labelled at 13s for the outsider) | G2: X-31 | H2: Moment the person passes the door | I2: High | J2: =COUNTIFS(Clips!$D:$D,A2,Clips!$E:$E,"violation") -> 2 | K2: =COUNTIFS(Clips!$D:$D,A2,Clips!$E:$E,"correct") -> 1 | L2: =COUNTIF(Case_Rule!$A:$A,A2) -> 1
A3: C-02 | B3: Outsider in the cash room | C3: Any time | D3: A non-staff person walks in and stands on the cashier side of the desk. | E3: Room stays closed; only the cashier is on the cashier side. | F3: X-30 @13s; X-33 (man enters ~10s, not labelled) | G3: X-31 | H3: Outsider enters the cashier zone | I3: High | J3: =COUNTIFS(Clips!$D:$D,A3,Clips!$E:$E,"violation") -> 1 | K3: =COUNTIFS(Clips!$D:$D,A3,Clips!$E:$E,"correct") -> 0 | L3: =COUNTIF(Case_Rule!$A:$A,A3) -> 1
A4: C-03 | B4: Second person during a service | C4: Client service | D4: While client 1 is being served, a second person walks in and hands the cashier a document. | E4: One client at a time; the next waits outside until the service ends. | F4: X-18 @20s | G4: X-19 | H4: Second person's handover | I4: High | J4: =COUNTIFS(Clips!$D:$D,A4,Clips!$E:$E,"violation") -> 1 | K4: =COUNTIFS(Clips!$D:$D,A4,Clips!$E:$E,"correct") -> 1 | L4: =COUNTIF(Case_Rule!$A:$A,A4) -> 1
A5: C-04 | B5: Cash accepted without ID | C5: Client service | D5: Client puts cash on the desk; no ID card or document is shown at any point; cashier processes it. | E5: Client hands over an ID card first; cashier checks it, then takes the cash. | F5: X-2 @10s | G5: X-1; X-3; X-5 | H5: First cash handover of the session | I5: Medium | J5: =COUNTIFS(Clips!$D:$D,A5,Clips!$E:$E,"violation") -> 1 | K5: =COUNTIFS(Clips!$D:$D,A5,Clips!$E:$E,"correct") -> 1 | L5: =COUNTIF(Case_Rule!$A:$A,A5) -> 1
A6: C-05 | B6: Client leaves before the count | C6: Client service | D6: Client leaves; the cashier runs his cash through the machine after he has gone. | E6: Client waits while his cash is counted, then leaves. | F6: X-34 @13s | G6: X-37; X-35 | H6: Client exit | I6: High | J6: =COUNTIFS(Clips!$D:$D,A6,Clips!$E:$E,"violation") -> 1 | K6: =COUNTIFS(Clips!$D:$D,A6,Clips!$E:$E,"correct") -> 1 | L6: =COUNTIF(Case_Rule!$A:$A,A6) -> 1
A7: C-06 | B7: Doubtful note returned to client | C7: Client service | D7: After the machine count the cashier hand-counts and hands part of the notes back to the client. | E7: A note rejected by the machine is kept, an act is drawn up. | F7: X-1 @22s | G7: X-3 | H7: Handover back to the client | I7: Low | J7: =COUNTIFS(Clips!$D:$D,A7,Clips!$E:$E,"violation") -> 1 | K7: =COUNTIFS(Clips!$D:$D,A7,Clips!$E:$E,"correct") -> 0 | L7: =COUNTIF(Case_Rule!$A:$A,A7) -> 1
A8: C-07 | B8: Next client while previous cash is on the desk | C8: Between clients | D8: Client 1 leaves, his cash stays open on the desk, client 2 walks in and sits down. | E8: Cashier puts client 1's cash into the safe or locked drawer before the next client. | F8: X-4 @57s; X-38 @33s | G8: X-5; X-19; X-35; X-39 | H8: Next client's entry | I8: High | J8: =COUNTIFS(Clips!$D:$D,A8,Clips!$E:$E,"violation") -> 2 | K8: =COUNTIFS(Clips!$D:$D,A8,Clips!$E:$E,"correct") -> 4 | L8: =COUNTIF(Case_Rule!$A:$A,A8) -> 1
A9: C-08 | B9: Cash of two clients merged | C9: Between clients | D9: Client 1's leftover cash is picked up together with client 2's notes. | E9: Each client's cash is handled and stacked separately. | F9: X-47 @68s (same file as X-4) | G9: X-5 | H9: Moment the stacks join | I9: Medium | J9: =COUNTIFS(Clips!$D:$D,A9,Clips!$E:$E,"violation") -> 1 | K9: =COUNTIFS(Clips!$D:$D,A9,Clips!$E:$E,"correct") -> 0 | L9: =COUNTIF(Case_Rule!$A:$A,A9) -> 1
A10: C-09 | B10: Safe left open while working | C10: Any time | D10: Cashier takes cash from the safe and works at the desk with the safe door wide open. | E10: Cashier closes the safe right after taking or putting cash. | F10: X-20 @5s | G10: X-21; X-8 | H10: Cashier walks away from the open safe | I10: High | J10: =COUNTIFS(Clips!$D:$D,A10,Clips!$E:$E,"violation") -> 1 | K10: =COUNTIFS(Clips!$D:$D,A10,Clips!$E:$E,"correct") -> 2 | L10: =COUNTIF(Case_Rule!$A:$A,A10) -> 1
A11: C-10 | B11: Collector handover without checks | C11: Cash collection | D11: Collector hands over the bag and leaves at once; no document shown, no joint check of the bag. | E11: Collector shows his card/document, cashier checks it, collector waits while the bag is checked. | F11: X-17 @7s | G11: X-16 | H11: Bag handover | I11: High | J11: =COUNTIFS(Clips!$D:$D,A11,Clips!$E:$E,"violation") -> 1 | K11: =COUNTIFS(Clips!$D:$D,A11,Clips!$E:$E,"correct") -> 1 | L11: =COUNTIF(Case_Rule!$A:$A,A11) -> 2
A12: C-11 | B12: Bag contents stored without recount | C12: Cash collection | D12: Cashier opens the bag and moves the bundles straight into the safe. | E12: Cashier recounts every bundle (machine and hand) before putting it in the safe. | F12: X-13 @47s | G12: X-14 | H12: Bundles go into the safe | I12: High | J12: =COUNTIFS(Clips!$D:$D,A12,Clips!$E:$E,"violation") -> 1 | K12: =COUNTIFS(Clips!$D:$D,A12,Clips!$E:$E,"correct") -> 1 | L12: =COUNTIF(Case_Rule!$A:$A,A12) -> 1
A13: C-12 | B13: Leaves with cash on the desk | C13: Leaving the workplace | D13: Cashier puts counted cash on the desk and walks out of the room. | E13: Cashier puts the cash into the safe and locks it before leaving. | F13: X-26 @9s | G13: X-27 | H13: Cashier stands and heads for the door | I13: High | J13: =COUNTIFS(Clips!$D:$D,A13,Clips!$E:$E,"violation") -> 1 | K13: =COUNTIFS(Clips!$D:$D,A13,Clips!$E:$E,"correct") -> 1 | L13: =COUNTIF(Case_Rule!$A:$A,A13) -> 1
... A21: C-20 | B21: Camera phone at the cash desk | C21: Any time | D21: Cashier has a phone with a camera at the desk (no clip in the set; extension for unseen types). | E21: Only communication devices without photo/video capture in the cash unit. | F21: (none) | G21: (none) | H21: Phone first visible | I21: n/a | J21: =COUNTIFS(Clips!$D:$D,A21,Clips!$E:$E,"violation") -> 0 | K21: =COUNTIFS(Clips!$D:$D,A21,Clips!$E:$E,"correct") -> 0 | L21: =COUNTIF(Case_Rule!$A:$A,A21) -> 1

Sheet Rules
A1: Rule ID | B1: Family | C1: Must be true | D1: Breach condition (engine) | E1: Signals needed | F1: Min duration (proposal) | G1: Timecode anchor | H1: Source (short) | I1: Source link | J1: Strength | K1: Status | L1: # cases linked
A2: A-DOOR-LOCK | B2: Access | C2: Door is closed and locked within ~5 s after anyone enters. | D2: ENTER(person) and no door-close / hand-on-door event within 5 s while the person walks to the desk. | E2: Person tracker; door zone; door state; hand pose | F2: 5 s | G2: Person passes the door | H2: NBRK 14, п.8, п.16(1) | I2: https://adilet.zan.kz/rus/docs/V2000020075 | J2: Indirect | K2: Confirmed | L2: =COUNTIF(Case_Rule!$B:$B,A2) -> 1
A3: A-OUTSIDER-ZONE | B3: Access | C3: Only the cashier stands in the cashier zone. | D3: A person other than the cashier stays inside the cashier zone. | E3: Person tracker; zones from calibration | F3: 2 s | G3: First frame in the zone | H3: NBRK 14, п.8; NBRK 231, п.75 | I3: https://adilet.zan.kz/rus/docs/V2000020075 | J3: Indirect | K3: Confirmed | L3: =COUNTIF(Case_Rule!$B:$B,A3) -> 1
A4: A-SECOND-PERSON | B4: Access | C4: One client at a time. | D4: Client session open and a second non-staff person hands an item to the cashier. | E4: Sessions; handover detection | F4: - | G4: Second person's handover | H4: NBRK 231, п.21, п.22 | I4: https://adilet.zan.kz/rus/docs/V1900019680 | J4: Indirect | K4: Confirmed | L4: =COUNTIF(Case_Rule!$B:$B,A4) -> 1
A5: C-ID-BEFORE-CASH | B5: Client checks | C5: Client shows an ID document before cash is accepted or issued. | D5: First HANDOVER(client to cashier, cash) of a session with no ID_SHOWN before it. | E5: ID card / document detector; handover | F5: whole session | G5: First cash handover | H5: NBRK 231, п.7, п.19 пп.1, п.31 пп.1 | I5: https://adilet.zan.kz/rus/docs/V1900019680 | J5: Direct | K5: Confirmed | L5: =COUNTIF(Case_Rule!$B:$B,A5) -> 1
A6: C-COUNT-BEFORE-EXIT | B6: Client checks | C6: Client's cash is counted while the client is present. | D6: EXIT(client) before COUNT_END for that client's cash. | E6: Counting machine running state; hand count; exit | F6: - | G6: Client exit | H6: NBRK 231, п.19 пп.2, п.20 | I6: https://adilet.zan.kz/rus/docs/V1900019680 | J6: Direct | K6: Confirmed | L6: =COUNTIF(Case_Rule!$B:$B,A6) -> 1
A7: C-REJECT-NOT-RETURNED | B7: Client checks | C7: A doubtful note is kept and an act drawn up; it is not returned. | D7: Note from the machine's reject pocket handed to the client. | E7: Counter reject event; handover | F7: - | G7: Handover to client | H7: NBRK 231, п.59-61 | I7: https://adilet.zan.kz/rus/docs/V1900019680 | J7: Direct | K7: Confirmed | L7: =COUNTIF(Case_Rule!$B:$B,A7) -> 1
A8: C-DETECTOR-CHECK | B8: Client checks | C8: Notes rejected by the counter are checked on the detector before re-stacking. | D8: Rejected note re-stacked with no detector use in between. | E8: Detector device state; hand pose | F8: - | G8: Re-stack moment | H8: NBRK 231, п.9, п.59 | I8: https://adilet.zan.kz/rus/docs/V1900019680 | J8: Weak | K8: Candidate | L8: =COUNTIF(Case_Rule!$B:$B,A8) -> 1
A9: S-CLEAN-DESK-HANDOVER | B9: Storage & desk | C9: When a new client enters, no cash from earlier sessions is on the desk. | D9: ENTER(client N+1) while cash tagged with session N is on the desk. | E9: Money detector; money-flow tracker; sessions | F9: - | G9: Next client's entry | H9: NBRK 231, п.20 | I9: https://adilet.zan.kz/rus/docs/V1900019680 | J9: Direct | K9: Confirmed | L9: =COUNTIF(Case_Rule!$B:$B,A9) -> 1
A10: S-NO-MERGE | B10: Storage & desk | C10: Cash of different sessions is never stacked together. | D10: Cash tagged N joins a stack tagged N+1. | E10: Money-flow tracker | F10: - | G10: Moment the stacks join | H10: NBRK 231, п.20, п.21 | I10: https://adilet.zan.kz/rus/docs/V1900019680 | J10: Direct | K10: Confirmed | L10: =COUNTIF(Case_Rule!$B:$B,A10) -> 1
A11: S-SAFE-CLOSED | B11: Storage & desk | C11: The safe is closed whenever the cashier is not using it. | D11: Safe door open while the cashier is away from the safe zone. | E11: Safe door state; person tracker | F11: 3 s | G11: Cashier leaves the safe zone | H11: NBRK 231, п.20 | I11: https://adilet.zan.kz/rus/docs/V1900019680 | J11: Indirect | K11: Confirmed | L11: =COUNTIF(Case_Rule!$B:$B,A11) -> 1
A12: K-COLLECTOR-DOC | B12: Cash collection | C12: The collector's accompanying document / ID is checked before the bag is accepted. | D12: HANDOVER(collector to cashier, bag) with no document shown during the collector's visit. | E12: Document detector; role = enters carrying a bag | F12: - | G12: Bag handover | H12: NBRK 231, п.24 пп.1-2 (п.106-107 to read) | I12: https://adilet.zan.kz/rus/docs/V1900019680 | J12: Direct | K12: Confirmed | L12: =COUNTIF(Case_Rule!$B:$B,A12) -> 1
A13: K-SEAL-CHECK | B13: Cash collection | C13: Bag and seal are inspected while the collector is present. | D13: Collector exits within ~5 s of the bag handover with no inspection of the bag. | E13: Person tracker; hand pose on the bag | F13: 5 s | G13: Collector exit | H13: NBRK 231, п.24 пп.3-4, п.25, п.94 | I13: https://adilet.zan.kz/rus/docs/V1900019680 | J13: Direct | K13: Confirmed | L13: =COUNTIF(Case_Rule!$B:$B,A13) -> 1
... A22: W-NO-CAMERA-PHONE | B22: Workplace conduct | C22: Only communication devices without photo/video capture in the cash unit. | D22: A phone visible in the cashier's hand or on the desk. | E22: Object detector (phone) | F22: 2 s | G22: Phone first visible | H22: NBRK 231, п.12 | I22: https://adilet.zan.kz/rus/docs/V1900019680 | J22: Direct | K22: Candidate | L22: =COUNTIF(Case_Rule!$B:$B,A22) -> 1

Sheet Case_Rule
A1: Case ID | B1: Rule ID | C1: Scenario (lookup) | D1: Source (lookup) | E1: Strength (lookup)
A2: C-01 | B2: A-DOOR-LOCK | C2: =IFERROR(INDEX(Cases!$B:$B,MATCH(A2,Cases!$A:$A,0)),"unknown case") -> Door left unlocked on entry | D2: =IFERROR(INDEX(Rules!$H:$H,MATCH(B2,Rules!$A:$A,0)),"unknown rule") -> NBRK 14, п.8, п.16(1) | E2: =IFERROR(INDEX(Rules!$J:$J,MATCH(B2,Rules!$A:$A,0)),"") -> Indirect
A3: C-02 | B3: A-OUTSIDER-ZONE | C3: =IFERROR(INDEX(Cases!$B:$B,MATCH(A3,Cases!$A:$A,0)),"unknown case") -> Outsider in the cash room | D3: =IFERROR(INDEX(Rules!$H:$H,MATCH(B3,Rules!$A:$A,0)),"unknown rule") -> NBRK 14, п.8; NBRK 231, п.75 | E3: =IFERROR(INDEX(Rules!$J:$J,MATCH(B3,Rules!$A:$A,0)),"") -> Indirect
A4: C-03 | B4: A-SECOND-PERSON | C4: =IFERROR(INDEX(Cases!$B:$B,MATCH(A4,Cases!$A:$A,0)),"unknown case") -> Second person during a service | D4: =IFERROR(INDEX(Rules!$H:$H,MATCH(B4,Rules!$A:$A,0)),"unknown rule") -> NBRK 231, п.21, п.22 | E4: =IFERROR(INDEX(Rules!$J:$J,MATCH(B4,Rules!$A:$A,0)),"") -> Indirect
A5: C-04 | B5: C-ID-BEFORE-CASH | C5: =IFERROR(INDEX(Cases!$B:$B,MATCH(A5,Cases!$A:$A,0)),"unknown case") -> Cash accepted without ID | D5: =IFERROR(INDEX(Rules!$H:$H,MATCH(B5,Rules!$A:$A,0)),"unknown rule") -> NBRK 231, п.7, п.19 пп.1, п.31 пп.1 | E5: =IFERROR(INDEX(Rules!$J:$J,MATCH(B5,Rules!$A:$A,0)),"") -> Direct
A6: C-05 | B6: C-COUNT-BEFORE-EXIT | C6: =IFERROR(INDEX(Cases!$B:$B,MATCH(A6,Cases!$A:$A,0)),"unknown case") -> Client leaves before the count | D6: =IFERROR(INDEX(Rules!$H:$H,MATCH(B6,Rules!$A:$A,0)),"unknown rule") -> NBRK 231, п.19 пп.2, п.20 | E6: =IFERROR(INDEX(Rules!$J:$J,MATCH(B6,Rules!$A:$A,0)),"") -> Direct
A7: C-06 | B7: C-REJECT-NOT-RETURNED | C7: =IFERROR(INDEX(Cases!$B:$B,MATCH(A7,Cases!$A:$A,0)),"unknown case") -> Doubtful note returned to client | D7: =IFERROR(INDEX(Rules!$H:$H,MATCH(B7,Rules!$A:$A,0)),"unknown rule") -> NBRK 231, п.59-61 | E7: =IFERROR(INDEX(Rules!$J:$J,MATCH(B7,Rules!$A:$A,0)),"") -> Direct
A8: C-07 | B8: S-CLEAN-DESK-HANDOVER | C8: =IFERROR(INDEX(Cases!$B:$B,MATCH(A8,Cases!$A:$A,0)),"unknown case") -> Next client while previous cash is on the desk | D8: =IFERROR(INDEX(Rules!$H:$H,MATCH(B8,Rules!$A:$A,0)),"unknown rule") -> NBRK 231, п.20 | E8: =IFERROR(INDEX(Rules!$J:$J,MATCH(B8,Rules!$A:$A,0)),"") -> Direct
A9: C-08 | B9: S-NO-MERGE | C9: =IFERROR(INDEX(Cases!$B:$B,MATCH(A9,Cases!$A:$A,0)),"unknown case") -> Cash of two clients merged | D9: =IFERROR(INDEX(Rules!$H:$H,MATCH(B9,Rules!$A:$A,0)),"unknown rule") -> NBRK 231, п.20, п.21 | E9: =IFERROR(INDEX(Rules!$J:$J,MATCH(B9,Rules!$A:$A,0)),"") -> Direct
A10: C-09 | B10: S-SAFE-CLOSED | C10: =IFERROR(INDEX(Cases!$B:$B,MATCH(A10,Cases!$A:$A,0)),"unknown case") -> Safe left open while working | D10: =IFERROR(INDEX(Rules!$H:$H,MATCH(B10,Rules!$A:$A,0)),"unknown rule") -> NBRK 231, п.20 | E10: =IFERROR(INDEX(Rules!$J:$J,MATCH(B10,Rules!$A:$A,0)),"") -> Indirect
A11: C-10 | B11: K-COLLECTOR-DOC | C11: =IFERROR(INDEX(Cases!$B:$B,MATCH(A11,Cases!$A:$A,0)),"unknown case") -> Collector handover without checks | D11: =IFERROR(INDEX(Rules!$H:$H,MATCH(B11,Rules!$A:$A,0)),"unknown rule") -> NBRK 231, п.24 пп.1-2 (п.106-107 to read) | E11: =IFERROR(INDEX(Rules!$J:$J,MATCH(B11,Rules!$A:$A,0)),"") -> Direct
A12: C-10 | B12: K-SEAL-CHECK | C12: =IFERROR(INDEX(Cases!$B:$B,MATCH(A12,Cases!$A:$A,0)),"unknown case") -> Collector handover without checks | D12: =IFERROR(INDEX(Rules!$H:$H,MATCH(B12,Rules!$A:$A,0)),"unknown rule") -> NBRK 231, п.24 пп.3-4, п.25, п.94 | E12: =IFERROR(INDEX(Rules!$J:$J,MATCH(B12,Rules!$A:$A,0)),"") -> Direct
A13: C-11 | B13: K-RECOUNT-BEFORE-SAFE | C13: =IFERROR(INDEX(Cases!$B:$B,MATCH(A13,Cases!$A:$A,0)),"unknown case") -> Bag contents stored without recount | D13: =IFERROR(INDEX(Rules!$H:$H,MATCH(B13,Rules!$A:$A,0)),"unknown rule") -> NBRK 231, п.42, п.74 | E13: =IFERROR(INDEX(Rules!$J:$J,MATCH(B13,Rules!$A:$A,0)),"") -> Indirect
... A23: C-20 | B23: W-NO-CAMERA-PHONE | C23: =IFERROR(INDEX(Cases!$B:$B,MATCH(A23,Cases!$A:$A,0)),"unknown case") -> Camera phone at the cash desk | D23: =IFERROR(INDEX(Rules!$H:$H,MATCH(B23,Rules!$A:$A,0)),"unknown rule") -> NBRK 231, п.12 | E23: =IFERROR(INDEX(Rules!$J:$J,MATCH(B23,Rules!$A:$A,0)),"") -> Direct

Sheet Clips
A1: Clip | B1: Label time (s) | C1: Label | D1: Case ID (primary) | E1: Role | F1: What is visible | G1: Confidence | H1: Duplicate of | I1: Camera layout
A2: X-1 | B2: 22 | C2: violation | D2: C-06 | E2: violation | F2: Notes from the machine hand-counted, part handed back to the client | G2: Low | I2: Client-facing desk
A3: X-2 | B3: 10 | C3: violation | D3: C-04 | E3: violation | F3: Cash placed on the desk with no ID shown | G3: Medium | I3: Client-facing desk
A4: X-3 | C4: no violation | D4: C-04 | E4: correct | F4: ID card shown, cash counted in the machine | I4: Client-facing desk
A5: X-4 | B5: 57 | C5: violation | D5: C-07 | E5: violation | F5: Client 1's cash on the desk as client 2 enters | G5: High | I5: Client-facing desk
A6: X-5 | C6: no violation | D6: C-07 | E6: correct | F6: Cash stored before the next client | I6: Client-facing desk
A7: X-8 | C7: no violation | D7: C-09 | E7: correct | F7: Cash into the safe, safe closed, paperwork | I7: Back-office desk
A8: X-10 | C8: no violation | D8: C-18 | E8: correct | F8: Cashier counts cash alone at the desk | I8: Back-office desk
A9: X-11 | B9: 18 | C9: violation | D9: C-15 | E9: violation | F9: Leaves at end of day, laptop on a working screen, machine on | G9: High | I9: Back-office desk
A10: X-12 | C10: no violation | D10: C-15 | E10: correct | F10: Laptop closed, machine off, safe locked, lights off | I10: Back-office desk
A11: X-13 | B11: 47 | C11: violation | D11: C-11 | E11: violation | F11: Bundles from the bag go straight into the safe | G11: High | I11: Back-office desk
A12: X-14 | C12: no violation | D12: C-11 | E12: correct | F12: Every bundle recounted, then the safe | I12: Back-office desk
A13: X-15 | B13: 15 | C13: violation | D13: C-13 | E13: violation | F13: Leaves with the packed cash bag on the desk | G13: High | I13: Back-office desk
A14: X-16 | C14: no violation | D14: C-10 | E14: correct | F14: Collector's card checked, collector waits | I14: Client-facing desk
A15: X-17 | B15: 7 | C15: violation | D15: C-10 | E15: violation | F15: Collector hands the bag and leaves at once | G15: High | I15: Client-facing desk
A16: X-18 | B16: 20 | C16: violation | D16: C-03 | E16: violation | F16: Second person hands a document during a service | G16: High | I16: Client-facing desk
A17: X-19 | C17: no violation | D17: C-03 | E17: correct | F17: One client at a time; cash to the safe between clients | I17: Client-facing desk
A18: X-20 | B18: 5 | C18: violation | D18: C-09 | E18: violation | F18: Safe door left open while working at the desk | G18: High | I18: Back-office desk
A19: X-21 | C19: no violation | D19: C-09 | E19: correct | F19: Cash taken, safe closed | I19: Back-office desk
A20: X-22 | B20: 14 | C20: violation | D20: C-16 | E20: violation | F20: Leaves at end of day; breach unclear | G20: Low | I20: Back-office desk
A21: X-23 | C21: no violation | D21: C-15 | E21: correct | F21: Laptop on the lock screen, safe locked, leaves | I21: Back-office desk
A22: X-24 | B22: 8 | C22: violation | D22: C-14 | E22: violation | F22: Leaves with a tablet and a cup on the desk | G22: Medium | I22: Back-office desk
A23: X-25 | C23: no violation | D23: C-14 | E23: correct | F23: Tablet and items into the safe before leaving | I23: Back-office desk
A24: X-26 | B24: 9 | C24: violation | D24: C-12 | E24: violation | F24: Leaves with counted cash on the desk | G24: High | I24: Back-office desk
A25: X-27 | C25: no violation | D25: C-12 | E25: correct | F25: Cash into the safe before leaving | I25: Back-office desk
A26: X-28 | B26: 7 | C26: violation | D26: C-15 | E26: violation | F26: Leaves with the laptop unlocked | G26: High | I26: Back-office desk
A27: X-29 | C27: no violation | D27: C-15 | E27: correct | F27: Laptop on the lock screen, leaves | I27: Back-office desk
A28: X-30 | B28: 13 | C28: violation | D28: C-02 | E28: violation | F28: Door not locked; a man stands on the cashier side | G28: High | I28: Desk near the door
A29: X-31 | C29: no violation | D29: C-01 | E29: correct | F29: Cashier turns back and locks the door | I29: Desk near the door
A30: X-32 | B30: 5 | C30: violation | D30: C-01 | E30: violation | F30: Cashier walks in without locking the door | G30: High | I30: Desk near the door
A31: X-33 | B31: 6 | C31: violation | D31: C-01 | E31: violation | F31: Door not locked; a man enters at ~10 s | G31: High | I31: Desk near the door
A32: X-34 | B32: 13 | C32: violation | D32: C-05 | E32: violation | F32: Client leaves before his cash is counted | G32: High | I32: Client-facing desk
A33: X-35 | C33: no violation | D33: C-07 | E33: correct | F33: Cash stored in the safe during the service | I33: Client-facing desk
A34: X-37 | C34: no violation | D34: C-05 | E34: correct | F34: Client waits while his cash is counted | I34: Client-facing desk
A35: X-38 | B35: 33 | C35: violation | D35: C-07 | E35: violation | F35: Client 1's notes on the desk as client 2 enters | G35: High | I35: Client-facing desk
A36: X-39 | C36: no violation | D36: C-07 | E36: correct | F36: Cash to the safe between clients | I36: Client-facing desk
A37: X-40 | B37: 17 | C37: violation | D37: C-17 | E37: violation | F37: Coat and handbag put on the cash desk | G37: High | I37: Desk near the door
A38: X-43 | C38: no violation | D38: C-18 | E38: correct | F38: Cashier works at the desk, no food | I38: Desk near the door
A39: X-44 | B39: 16 | C39: violation | D39: C-19 | E39: violation | F39: Notes re-stacked by hand, detector not used | G39: Low | I39: Desk near the door
A40: X-45 | C40: no violation | D40: C-19 | E40: correct | F40: Each note checked on the detector | I40: Desk near the door
...

Sheet Open_Questions
A1: # | B1: Question | C1: Why it matters | D1: My recommendation | E1: Your decision | F1: Status
A2: Q-01 | B2: X-22: what is the breach? | C2: One labelled clip has no rule yet; it can't be trained or tested. | D2: Re-watch at full resolution against X-23. Until then keep L-SAFE-LOCKED-ON-LEAVE as a candidate and leave X-22 out of threshold tuning. | F2: Open
A3: Q-02 | B3: Door left unlocked AND an outsider walks in later (X-30, X-33): report one violation or two? | C3: X-30 is labelled at the outsider (13 s), X-33 at the entry (6 s). | D3: Report both, earliest first. The verdict is per video; extra true events don't hurt. | F3: Open
A4: Q-03 | B4: FAQ 32 says every violation has an open norm. Which clause covers eating at the desk? | C4: W-NO-FOOD has no explicit clause; criterion 4 penalises weak citations. | D4: Search NBRK and sanitary acts once more. If nothing is found, cite NBRK 231 п.12 and mark it Weak. | F4: Open
A5: Q-04 | B5: Which timecode for missed actions (FAQ 10 leaves it to the team)? | C5: Criterion 2 checks the exact frame. | D5: The moment the action should have happened: the cash handover for a missing ID, the client's exit for a missing count, the entry for the door. | F5: Open
A6: Q-05 | B6: How do we tell cashier, client, collector and outsider apart without faces? | C6: Face recognition is banned (FAQ 29); roles drive half the rules. | D6: Cashier = person who sits on the cashier side; collector = enters carrying a bag; client = sits on the client side; anyone else on the cashier side = outsider. | F6: Open
A7: Q-06 | B7: Threshold policy: misses are unacceptable, false alarms should be few. | C7: Sets every min-duration in the Rules sheet. | D7: Tune so all 22 labelled events fire first, then cut false alarms on the 20 correct clips. | F7: Open
A8: Q-07 | B8: Unseen violation types in the test: what does the VLM fallback report? | C8: Free-text reports with no rule hurt criteria 3 and 4. | D8: Report only when the VLM's description matches a rule in this sheet; add new rules here (C-20 shows the pattern). | F8: Open
A9: Q-08 | B9: Final test is shot from a new angle: what if the safe or door is out of view? | C9: Rules that need a missing object can't be checked. | D9: Switch those rules off for that video and say so in the result, instead of guessing. | F9: Open
A10: Q-09 | B10: X-4 and X-47 are the same file with different labels (57 s, 68 s). | C10: Affects how we score ourselves on the training set. | D10: Treat both labels as valid events of one video. | F10: Open
A11: Q-10 | B11: Does the cashier handle a phone in any training clip? | C11: Decides whether W-NO-CAMERA-PHONE could fire on 'correct' clips. | D11: Check X-20 and X-26 frames before enabling the rule. | F11: Open
